<?xml version="1.0"?>
<robot name="origins">

<material name="black">
    <color rgba="0 0 0 0.5"/>
  </material>
<material name="white">
    <color rgba="1 1 1 0.5"/>
  </material>

<link name="base_link">
    <visual>
      <geometry>
        <box size="0.5 0.5 0.1 "/>
      </geometry>
      <material name="black"/>
    </visual>
    <collision>
        <geometry>
        <box size="0.5 0.5 0.1 "/>
      </geometry>
    </collision>
    <inertial>
      <mass value="10"/>
      <inertia ixx="1.0" ixy="0.0" ixz="0.0" iyy="1.0" iyz="0.0" izz="1.0"/>
    </inertial>
</link>

<link name="front_left">
    <visual>
      <geometry>
         <cylinder length="0.05" radius="0.05"/>
      </geometry>
      <origin rpy="0 1.55 1.55" xyz="0 0 0"/>
    </visual>
  </link>

<joint name="base_to_front_left" type="continuous">
    <axis rpy="0 0 0" xyz="0 1 0"/>
    <parent link="base_link"/>
    <child link="front_left"/>
    <origin xyz="0.25 0.25 -0.1"/> 
  </joint>

<link name="front_right">
    <visual>
      <geometry>
         <cylinder length="0.05" radius="0.05"/>
      </geometry>
      <origin rpy="0 1.55 1.55" xyz="0 0 0"/>
    </visual>
  </link>

<joint name="base_to_front_right" type="continuous">
    <axis rpy="0 0 0" xyz="0 1 0"/>
    <parent link="base_link"/>
    <child link="front_right"/>
    <origin xyz="0.25 -0.25 -0.1"/> 
  </joint>


<link name="back_left">
    <visual>
      <geometry>
         <cylinder length="0.05" radius="0.05"/>
      </geometry>
      <origin rpy="0 1.55 1.55" xyz="0 0 0"/>
    </visual>
  </link>

<joint name="base_to_back_left" type="continuous">
    <axis rpy="0 0 0" xyz="0 1 0"/>
    <parent link="base_link"/>
    <child link="back_left"/>
    <origin xyz="-0.25 0.25 -0.1"/> 
  </joint>


<link name="back_right">
    <visual>
      <geometry>
         <cylinder length="0.05" radius="0.05"/>
      </geometry>
      <origin rpy="0 1.55 1.55" xyz="0 0 0"/>
    </visual>
  </link>

<joint name="base_to_back_right" type="continuous">
    <!-- axis rpy="0 0 0"  xyz="0 1 0"(rotate about axis y) -->
    <axis rpy="0 0 0" xyz="0 1 0"/>
    <parent link="base_link"/>
    <child link="back_right"/>
    <origin xyz="-0.25 -0.25 -0.1"/> 
  </joint>

<link name="uv">
    <visual>
      <geometry>
         <cylinder length="1" radius="0.1"/>
      </geometry>
      <origin rpy="0 0 0" xyz="0 0 0.5"/>
      <material name="white"/>
    </visual>
  </link>

<joint name="base_to_uv" type="fixed">
    <parent link="base_link"/>
    <child link="uv"/>
    <origin xyz="0 0 0.05"/> 
  </joint>



</robot>